2022-03-06 23:43:31,600 INFO werkzeug MainThread :  * Running on http://127.0.0.1:5000/ (Press CTRL+C to quit)
2022-03-06 23:43:39,183 INFO werkzeug Thread-1 : 127.0.0.1 - - [06/Mar/2022 23:43:39] "GET /test HTTP/1.1" 200 -
2022-03-07 20:32:29,747 INFO werkzeug MainThread :  * Running on http://127.0.0.1:5000/ (Press CTRL+C to quit)
2022-03-07 20:32:54,748 INFO werkzeug Thread-1 : 127.0.0.1 - - [07/Mar/2022 20:32:54] "POST /datatable HTTP/1.1" 200 -
2022-03-07 20:37:03,927 INFO werkzeug MainThread :  * Running on http://127.0.0.1:5000/ (Press CTRL+C to quit)
2022-03-07 20:37:10,763 INFO werkzeug Thread-1 : 127.0.0.1 - - [07/Mar/2022 20:37:10] "POST /datatable HTTP/1.1" 200 -
2022-03-12 07:05:03,371 INFO werkzeug MainThread :  * Running on http://127.0.0.1:5000/ (Press CTRL+C to quit)
2022-03-12 07:05:06,823 INFO werkzeug Thread-1 : 127.0.0.1 - - [12/Mar/2022 07:05:06] "POST /login_user HTTP/1.1" 200 -
2022-03-13 22:58:40,850 INFO werkzeug MainThread :  * Running on http://127.0.0.1:5000/ (Press CTRL+C to quit)
2022-03-15 20:06:09,954 INFO werkzeug MainThread :  * Running on http://127.0.0.1:5000/ (Press CTRL+C to quit)
2022-03-15 20:08:45,833 INFO werkzeug Thread-1 : 127.0.0.1 - - [15/Mar/2022 20:08:45] "GET /load_banner_news HTTP/1.1" 200 -
2022-03-15 20:09:25,022 INFO werkzeug Thread-2 : 127.0.0.1 - - [15/Mar/2022 20:09:25] "GET /load_banner_news HTTP/1.1" 200 -
2022-03-15 20:09:42,993 INFO werkzeug Thread-3 : 127.0.0.1 - - [15/Mar/2022 20:09:42] "[33mGET /mobile/myorders HTTP/1.1[0m" 404 -
2022-03-15 20:11:10,802 INFO werkzeug MainThread :  * Running on http://127.0.0.1:5000/ (Press CTRL+C to quit)
2022-03-15 20:11:13,785 INFO werkzeug Thread-1 : 127.0.0.1 - - [15/Mar/2022 20:11:13] "GET /mobile/myorders HTTP/1.1" 200 -
2022-03-15 20:29:33,164 INFO werkzeug MainThread :  * Running on http://127.0.0.1:5000/ (Press CTRL+C to quit)
2022-03-15 20:29:40,669 INFO werkzeug Thread-1 : 127.0.0.1 - - [15/Mar/2022 20:29:40] "GET /mobile/load_video_banner HTTP/1.1" 200 -
2022-03-15 20:29:50,046 INFO werkzeug Thread-2 : 127.0.0.1 - - [15/Mar/2022 20:29:50] "GET /mobile/load_banner_news HTTP/1.1" 200 -
2022-03-15 20:35:09,703 INFO werkzeug MainThread :  * Running on http://127.0.0.1:5000/ (Press CTRL+C to quit)
2022-03-15 20:35:47,014 INFO werkzeug Thread-1 : 127.0.0.1 - - [15/Mar/2022 20:35:47] "POST /mobile/warga_login HTTP/1.1" 200 -
2022-03-15 20:36:23,879 INFO werkzeug Thread-2 : 127.0.0.1 - - [15/Mar/2022 20:36:23] "[31m[1mPOST /mobile/check_rate?idworkorder=100159798 HTTP/1.1[0m" 401 -
2022-03-15 20:36:44,238 INFO werkzeug Thread-3 : 127.0.0.1 - - [15/Mar/2022 20:36:44] "POST /mobile/check_rate?idworkorder=100159798 HTTP/1.1" 200 -
2022-03-17 07:50:29,630 INFO werkzeug MainThread :  * Running on http://127.0.0.1:5000/ (Press CTRL+C to quit)
2022-03-22 22:22:07,603 INFO werkzeug MainThread :  * Running on http://127.0.0.1:5000/ (Press CTRL+C to quit)
2022-03-22 22:23:08,830 INFO werkzeug Thread-1 : 127.0.0.1 - - [22/Mar/2022 22:23:08] "[31m[1mPOST /mobile/check_rate?idworkorder=100159798 HTTP/1.1[0m" 401 -
2022-03-22 22:33:42,229 INFO werkzeug Thread-2 : 127.0.0.1 - - [22/Mar/2022 22:33:42] "[33mPOST /cc/login_user HTTP/1.1[0m" 404 -
2022-03-23 00:13:36,753 INFO werkzeug Thread-3 : 127.0.0.1 - - [23/Mar/2022 00:13:36] "[33mPOST /cc/login_user HTTP/1.1[0m" 404 -
2022-03-23 00:14:10,047 INFO werkzeug MainThread :  * Running on http://127.0.0.1:5000/ (Press CTRL+C to quit)
2022-03-23 00:14:11,893 INFO werkzeug Thread-1 : 127.0.0.1 - - [23/Mar/2022 00:14:11] "[33mPOST /cc/login_user HTTP/1.1[0m" 404 -
2022-03-23 00:14:52,489 INFO werkzeug MainThread :  * Running on http://127.0.0.1:5000/ (Press CTRL+C to quit)
2022-03-23 00:14:53,980 INFO werkzeug Thread-1 : 127.0.0.1 - - [23/Mar/2022 00:14:53] "[33mPOST /cc/login_user HTTP/1.1[0m" 404 -
2022-03-23 00:14:55,584 INFO werkzeug Thread-2 : 127.0.0.1 - - [23/Mar/2022 00:14:55] "[33mPOST /cc/login_user HTTP/1.1[0m" 404 -
2022-03-23 00:18:08,367 INFO werkzeug MainThread :  * Running on http://127.0.0.1:5000/ (Press CTRL+C to quit)
2022-03-23 00:18:14,477 ERROR main Thread-1 : Exception on /cc/login_user [POST]
Traceback (most recent call last):
  File "c:\users\renow\pycharmprojects\callcenter-backend\venv\lib\site-packages\mysql\connector\connection_cext.py", line 523, in cmd_query
    self._cmysql.query(query,
_mysql_connector.MySQLInterfaceError: Unknown column 'satwil_id' in 'field list'

During handling of the above exception, another exception occurred:

Traceback (most recent call last):
  File "c:\users\renow\pycharmprojects\callcenter-backend\venv\lib\site-packages\flask\app.py", line 2073, in wsgi_app
    response = self.full_dispatch_request()
  File "c:\users\renow\pycharmprojects\callcenter-backend\venv\lib\site-packages\flask\app.py", line 1518, in full_dispatch_request
    rv = self.handle_user_exception(e)
  File "c:\users\renow\pycharmprojects\callcenter-backend\venv\lib\site-packages\flask_cors\extension.py", line 165, in wrapped_function
    return cors_after_request(app.make_response(f(*args, **kwargs)))
  File "c:\users\renow\pycharmprojects\callcenter-backend\venv\lib\site-packages\flask\app.py", line 1516, in full_dispatch_request
    rv = self.dispatch_request()
  File "c:\users\renow\pycharmprojects\callcenter-backend\venv\lib\site-packages\flask\app.py", line 1502, in dispatch_request
    return self.ensure_sync(self.view_functions[rule.endpoint])(**req.view_args)
  File "C:\Users\renow\PycharmProjects\brimob-be\cc.py", line 35, in login_user
    res = authenticate_user(username, password)
  File "C:\Users\renow\PycharmProjects\brimob-be\cc.py", line 41, in authenticate_user
    cursor.execute(query, (username,))
  File "c:\users\renow\pycharmprojects\callcenter-backend\venv\lib\site-packages\mysql\connector\cursor_cext.py", line 269, in execute
    result = self._cnx.cmd_query(stmt, raw=self._raw,
  File "c:\users\renow\pycharmprojects\callcenter-backend\venv\lib\site-packages\mysql\connector\connection_cext.py", line 528, in cmd_query
    raise errors.get_mysql_exception(exc.errno, msg=exc.msg,
mysql.connector.errors.ProgrammingError: 1054 (42S22): Unknown column 'satwil_id' in 'field list'
2022-03-23 00:18:14,532 INFO werkzeug Thread-1 : 127.0.0.1 - - [23/Mar/2022 00:18:14] "[35m[1mPOST /cc/login_user HTTP/1.1[0m" 500 -
2022-03-23 00:18:22,033 ERROR main Thread-2 : Exception on /cc/login_user [POST]
Traceback (most recent call last):
  File "c:\users\renow\pycharmprojects\callcenter-backend\venv\lib\site-packages\mysql\connector\connection_cext.py", line 523, in cmd_query
    self._cmysql.query(query,
_mysql_connector.MySQLInterfaceError: Unknown column 'satwil_id' in 'field list'

During handling of the above exception, another exception occurred:

Traceback (most recent call last):
  File "c:\users\renow\pycharmprojects\callcenter-backend\venv\lib\site-packages\flask\app.py", line 2073, in wsgi_app
    response = self.full_dispatch_request()
  File "c:\users\renow\pycharmprojects\callcenter-backend\venv\lib\site-packages\flask\app.py", line 1518, in full_dispatch_request
    rv = self.handle_user_exception(e)
  File "c:\users\renow\pycharmprojects\callcenter-backend\venv\lib\site-packages\flask_cors\extension.py", line 165, in wrapped_function
    return cors_after_request(app.make_response(f(*args, **kwargs)))
  File "c:\users\renow\pycharmprojects\callcenter-backend\venv\lib\site-packages\flask\app.py", line 1516, in full_dispatch_request
    rv = self.dispatch_request()
  File "c:\users\renow\pycharmprojects\callcenter-backend\venv\lib\site-packages\flask\app.py", line 1502, in dispatch_request
    return self.ensure_sync(self.view_functions[rule.endpoint])(**req.view_args)
  File "C:\Users\renow\PycharmProjects\brimob-be\cc.py", line 35, in login_user
    res = authenticate_user(username, password)
  File "C:\Users\renow\PycharmProjects\brimob-be\cc.py", line 41, in authenticate_user
    cursor.execute(query, (username,))
  File "c:\users\renow\pycharmprojects\callcenter-backend\venv\lib\site-packages\mysql\connector\cursor_cext.py", line 269, in execute
    result = self._cnx.cmd_query(stmt, raw=self._raw,
  File "c:\users\renow\pycharmprojects\callcenter-backend\venv\lib\site-packages\mysql\connector\connection_cext.py", line 528, in cmd_query
    raise errors.get_mysql_exception(exc.errno, msg=exc.msg,
mysql.connector.errors.ProgrammingError: 1054 (42S22): Unknown column 'satwil_id' in 'field list'
2022-03-23 00:18:22,037 INFO werkzeug Thread-2 : 127.0.0.1 - - [23/Mar/2022 00:18:22] "[35m[1mPOST /cc/login_user HTTP/1.1[0m" 500 -
2022-03-23 00:18:37,224 INFO werkzeug MainThread :  * Running on http://127.0.0.1:5000/ (Press CTRL+C to quit)
2022-03-23 00:18:39,167 ERROR main Thread-1 : Exception on /cc/login_user [POST]
Traceback (most recent call last):
  File "c:\users\renow\pycharmprojects\callcenter-backend\venv\lib\site-packages\mysql\connector\connection_cext.py", line 523, in cmd_query
    self._cmysql.query(query,
_mysql_connector.MySQLInterfaceError: Unknown column 'satwil_id' in 'field list'

During handling of the above exception, another exception occurred:

Traceback (most recent call last):
  File "c:\users\renow\pycharmprojects\callcenter-backend\venv\lib\site-packages\flask\app.py", line 2073, in wsgi_app
    response = self.full_dispatch_request()
  File "c:\users\renow\pycharmprojects\callcenter-backend\venv\lib\site-packages\flask\app.py", line 1518, in full_dispatch_request
    rv = self.handle_user_exception(e)
  File "c:\users\renow\pycharmprojects\callcenter-backend\venv\lib\site-packages\flask_cors\extension.py", line 165, in wrapped_function
    return cors_after_request(app.make_response(f(*args, **kwargs)))
  File "c:\users\renow\pycharmprojects\callcenter-backend\venv\lib\site-packages\flask\app.py", line 1516, in full_dispatch_request
    rv = self.dispatch_request()
  File "c:\users\renow\pycharmprojects\callcenter-backend\venv\lib\site-packages\flask\app.py", line 1502, in dispatch_request
    return self.ensure_sync(self.view_functions[rule.endpoint])(**req.view_args)
  File "C:\Users\renow\PycharmProjects\brimob-be\cc.py", line 35, in login_user
    res = authenticate_user(username, password)
  File "C:\Users\renow\PycharmProjects\brimob-be\cc.py", line 41, in authenticate_user
    cursor.execute(query, (username,))
  File "c:\users\renow\pycharmprojects\callcenter-backend\venv\lib\site-packages\mysql\connector\cursor_cext.py", line 269, in execute
    result = self._cnx.cmd_query(stmt, raw=self._raw,
  File "c:\users\renow\pycharmprojects\callcenter-backend\venv\lib\site-packages\mysql\connector\connection_cext.py", line 528, in cmd_query
    raise errors.get_mysql_exception(exc.errno, msg=exc.msg,
mysql.connector.errors.ProgrammingError: 1054 (42S22): Unknown column 'satwil_id' in 'field list'
2022-03-23 00:18:39,173 INFO werkzeug Thread-1 : 127.0.0.1 - - [23/Mar/2022 00:18:39] "[35m[1mPOST /cc/login_user HTTP/1.1[0m" 500 -
2022-03-23 00:24:51,678 INFO werkzeug Thread-2 : 127.0.0.1 - - [23/Mar/2022 00:24:51] "GET /mobile/load_video_banner HTTP/1.1" 200 -
2022-03-23 00:29:01,407 ERROR main Thread-3 : Exception on /cc/login_user [POST]
Traceback (most recent call last):
  File "c:\users\renow\pycharmprojects\callcenter-backend\venv\lib\site-packages\mysql\connector\connection_cext.py", line 523, in cmd_query
    self._cmysql.query(query,
_mysql_connector.MySQLInterfaceError: Unknown column 'satwil_id' in 'field list'

During handling of the above exception, another exception occurred:

Traceback (most recent call last):
  File "c:\users\renow\pycharmprojects\callcenter-backend\venv\lib\site-packages\flask\app.py", line 2073, in wsgi_app
    response = self.full_dispatch_request()
  File "c:\users\renow\pycharmprojects\callcenter-backend\venv\lib\site-packages\flask\app.py", line 1518, in full_dispatch_request
    rv = self.handle_user_exception(e)
  File "c:\users\renow\pycharmprojects\callcenter-backend\venv\lib\site-packages\flask_cors\extension.py", line 165, in wrapped_function
    return cors_after_request(app.make_response(f(*args, **kwargs)))
  File "c:\users\renow\pycharmprojects\callcenter-backend\venv\lib\site-packages\flask\app.py", line 1516, in full_dispatch_request
    rv = self.dispatch_request()
  File "c:\users\renow\pycharmprojects\callcenter-backend\venv\lib\site-packages\flask\app.py", line 1502, in dispatch_request
    return self.ensure_sync(self.view_functions[rule.endpoint])(**req.view_args)
  File "C:\Users\renow\PycharmProjects\brimob-be\cc.py", line 35, in login_user
    res = authenticate_user(username, password)
  File "C:\Users\renow\PycharmProjects\brimob-be\cc.py", line 41, in authenticate_user
    cursor.execute(query, (username,))
  File "c:\users\renow\pycharmprojects\callcenter-backend\venv\lib\site-packages\mysql\connector\cursor_cext.py", line 269, in execute
    result = self._cnx.cmd_query(stmt, raw=self._raw,
  File "c:\users\renow\pycharmprojects\callcenter-backend\venv\lib\site-packages\mysql\connector\connection_cext.py", line 528, in cmd_query
    raise errors.get_mysql_exception(exc.errno, msg=exc.msg,
mysql.connector.errors.ProgrammingError: 1054 (42S22): Unknown column 'satwil_id' in 'field list'
2022-03-23 00:29:01,408 INFO werkzeug Thread-3 : 127.0.0.1 - - [23/Mar/2022 00:29:01] "[35m[1mPOST /cc/login_user HTTP/1.1[0m" 500 -
2022-03-23 00:29:08,177 INFO werkzeug Thread-4 : 127.0.0.1 - - [23/Mar/2022 00:29:08] "[33mPOST /login_user HTTP/1.1[0m" 404 -
2022-03-23 00:29:14,685 ERROR main Thread-5 : Exception on /cc/login_user [POST]
Traceback (most recent call last):
  File "c:\users\renow\pycharmprojects\callcenter-backend\venv\lib\site-packages\mysql\connector\connection_cext.py", line 523, in cmd_query
    self._cmysql.query(query,
_mysql_connector.MySQLInterfaceError: Unknown column 'satwil_id' in 'field list'

During handling of the above exception, another exception occurred:

Traceback (most recent call last):
  File "c:\users\renow\pycharmprojects\callcenter-backend\venv\lib\site-packages\flask\app.py", line 2073, in wsgi_app
    response = self.full_dispatch_request()
  File "c:\users\renow\pycharmprojects\callcenter-backend\venv\lib\site-packages\flask\app.py", line 1518, in full_dispatch_request
    rv = self.handle_user_exception(e)
  File "c:\users\renow\pycharmprojects\callcenter-backend\venv\lib\site-packages\flask_cors\extension.py", line 165, in wrapped_function
    return cors_after_request(app.make_response(f(*args, **kwargs)))
  File "c:\users\renow\pycharmprojects\callcenter-backend\venv\lib\site-packages\flask\app.py", line 1516, in full_dispatch_request
    rv = self.dispatch_request()
  File "c:\users\renow\pycharmprojects\callcenter-backend\venv\lib\site-packages\flask\app.py", line 1502, in dispatch_request
    return self.ensure_sync(self.view_functions[rule.endpoint])(**req.view_args)
  File "C:\Users\renow\PycharmProjects\brimob-be\cc.py", line 35, in login_user
    res = authenticate_user(username, password)
  File "C:\Users\renow\PycharmProjects\brimob-be\cc.py", line 41, in authenticate_user
    cursor.execute(query, (username,))
  File "c:\users\renow\pycharmprojects\callcenter-backend\venv\lib\site-packages\mysql\connector\cursor_cext.py", line 269, in execute
    result = self._cnx.cmd_query(stmt, raw=self._raw,
  File "c:\users\renow\pycharmprojects\callcenter-backend\venv\lib\site-packages\mysql\connector\connection_cext.py", line 528, in cmd_query
    raise errors.get_mysql_exception(exc.errno, msg=exc.msg,
mysql.connector.errors.ProgrammingError: 1054 (42S22): Unknown column 'satwil_id' in 'field list'
2022-03-23 00:29:14,688 INFO werkzeug Thread-5 : 127.0.0.1 - - [23/Mar/2022 00:29:14] "[35m[1mPOST /cc/login_user HTTP/1.1[0m" 500 -
2022-03-23 00:29:39,849 ERROR main Thread-6 : Exception on /cc/login_user [POST]
Traceback (most recent call last):
  File "c:\users\renow\pycharmprojects\callcenter-backend\venv\lib\site-packages\mysql\connector\connection_cext.py", line 523, in cmd_query
    self._cmysql.query(query,
_mysql_connector.MySQLInterfaceError: Unknown column 'satwil_id' in 'field list'

During handling of the above exception, another exception occurred:

Traceback (most recent call last):
  File "c:\users\renow\pycharmprojects\callcenter-backend\venv\lib\site-packages\flask\app.py", line 2073, in wsgi_app
    response = self.full_dispatch_request()
  File "c:\users\renow\pycharmprojects\callcenter-backend\venv\lib\site-packages\flask\app.py", line 1518, in full_dispatch_request
    rv = self.handle_user_exception(e)
  File "c:\users\renow\pycharmprojects\callcenter-backend\venv\lib\site-packages\flask_cors\extension.py", line 165, in wrapped_function
    return cors_after_request(app.make_response(f(*args, **kwargs)))
  File "c:\users\renow\pycharmprojects\callcenter-backend\venv\lib\site-packages\flask\app.py", line 1516, in full_dispatch_request
    rv = self.dispatch_request()
  File "c:\users\renow\pycharmprojects\callcenter-backend\venv\lib\site-packages\flask\app.py", line 1502, in dispatch_request
    return self.ensure_sync(self.view_functions[rule.endpoint])(**req.view_args)
  File "C:\Users\renow\PycharmProjects\brimob-be\cc.py", line 35, in login_user
    def authenticate_user(username, password):
  File "C:\Users\renow\PycharmProjects\brimob-be\cc.py", line 41, in authenticate_user
    level_user = ''
  File "c:\users\renow\pycharmprojects\callcenter-backend\venv\lib\site-packages\mysql\connector\cursor_cext.py", line 269, in execute
    result = self._cnx.cmd_query(stmt, raw=self._raw,
  File "c:\users\renow\pycharmprojects\callcenter-backend\venv\lib\site-packages\mysql\connector\connection_cext.py", line 528, in cmd_query
    raise errors.get_mysql_exception(exc.errno, msg=exc.msg,
mysql.connector.errors.ProgrammingError: 1054 (42S22): Unknown column 'satwil_id' in 'field list'
2022-03-23 00:29:39,852 INFO werkzeug Thread-6 : 127.0.0.1 - - [23/Mar/2022 00:29:39] "[35m[1mPOST /cc/login_user HTTP/1.1[0m" 500 -
2022-03-23 00:29:49,663 INFO werkzeug MainThread :  * Running on http://127.0.0.1:5000/ (Press CTRL+C to quit)
2022-03-23 00:29:52,987 INFO werkzeug Thread-1 : 127.0.0.1 - - [23/Mar/2022 00:29:52] "POST /cc/login_user HTTP/1.1" 200 -
2022-03-23 00:30:40,369 INFO werkzeug MainThread :  * Running on http://127.0.0.1:5000/ (Press CTRL+C to quit)
2022-03-23 00:30:43,010 ERROR main Thread-1 : Exception on /cc/login_user [POST]
Traceback (most recent call last):
  File "c:\users\renow\pycharmprojects\callcenter-backend\venv\lib\site-packages\flask\app.py", line 2073, in wsgi_app
    response = self.full_dispatch_request()
  File "c:\users\renow\pycharmprojects\callcenter-backend\venv\lib\site-packages\flask\app.py", line 1518, in full_dispatch_request
    rv = self.handle_user_exception(e)
  File "c:\users\renow\pycharmprojects\callcenter-backend\venv\lib\site-packages\flask_cors\extension.py", line 165, in wrapped_function
    return cors_after_request(app.make_response(f(*args, **kwargs)))
  File "c:\users\renow\pycharmprojects\callcenter-backend\venv\lib\site-packages\flask\app.py", line 1516, in full_dispatch_request
    rv = self.dispatch_request()
  File "c:\users\renow\pycharmprojects\callcenter-backend\venv\lib\site-packages\flask\app.py", line 1502, in dispatch_request
    return self.ensure_sync(self.view_functions[rule.endpoint])(**req.view_args)
  File "C:\Users\renow\PycharmProjects\brimob-be\cc.py", line 35, in login_user
    res = authenticate_user(username, password)
  File "C:\Users\renow\PycharmProjects\brimob-be\cc.py", line 58, in authenticate_user
    satwil = record[0]['satwil_id']
KeyError: 'satwil_id'
2022-03-23 00:30:43,018 INFO werkzeug Thread-1 : 127.0.0.1 - - [23/Mar/2022 00:30:43] "[35m[1mPOST /cc/login_user HTTP/1.1[0m" 500 -
2022-03-23 00:39:53,669 INFO werkzeug MainThread :  * Running on http://127.0.0.1:5000/ (Press CTRL+C to quit)
2022-03-23 00:39:56,072 ERROR main Thread-1 : Exception on /cc/login_user [POST]
Traceback (most recent call last):
  File "c:\users\renow\pycharmprojects\callcenter-backend\venv\lib\site-packages\mysql\connector\connection_cext.py", line 523, in cmd_query
    self._cmysql.query(query,
_mysql_connector.MySQLInterfaceError: Unknown column 'position.position_id' in 'on clause'

During handling of the above exception, another exception occurred:

Traceback (most recent call last):
  File "c:\users\renow\pycharmprojects\callcenter-backend\venv\lib\site-packages\flask\app.py", line 2073, in wsgi_app
    response = self.full_dispatch_request()
  File "c:\users\renow\pycharmprojects\callcenter-backend\venv\lib\site-packages\flask\app.py", line 1518, in full_dispatch_request
    rv = self.handle_user_exception(e)
  File "c:\users\renow\pycharmprojects\callcenter-backend\venv\lib\site-packages\flask_cors\extension.py", line 165, in wrapped_function
    return cors_after_request(app.make_response(f(*args, **kwargs)))
  File "c:\users\renow\pycharmprojects\callcenter-backend\venv\lib\site-packages\flask\app.py", line 1516, in full_dispatch_request
    rv = self.dispatch_request()
  File "c:\users\renow\pycharmprojects\callcenter-backend\venv\lib\site-packages\flask\app.py", line 1502, in dispatch_request
    return self.ensure_sync(self.view_functions[rule.endpoint])(**req.view_args)
  File "C:\Users\renow\PycharmProjects\brimob-be\cc.py", line 35, in login_user
    res = authenticate_user(username, password)
  File "C:\Users\renow\PycharmProjects\brimob-be\cc.py", line 42, in authenticate_user
    cursor.execute(query, (username,))
  File "c:\users\renow\pycharmprojects\callcenter-backend\venv\lib\site-packages\mysql\connector\cursor_cext.py", line 269, in execute
    result = self._cnx.cmd_query(stmt, raw=self._raw,
  File "c:\users\renow\pycharmprojects\callcenter-backend\venv\lib\site-packages\mysql\connector\connection_cext.py", line 528, in cmd_query
    raise errors.get_mysql_exception(exc.errno, msg=exc.msg,
mysql.connector.errors.ProgrammingError: 1054 (42S22): Unknown column 'position.position_id' in 'on clause'
2022-03-23 00:39:56,075 INFO werkzeug Thread-1 : 127.0.0.1 - - [23/Mar/2022 00:39:56] "[35m[1mPOST /cc/login_user HTTP/1.1[0m" 500 -
2022-03-23 00:40:20,295 ERROR main Thread-2 : Exception on /cc/login_user [POST]
Traceback (most recent call last):
  File "c:\users\renow\pycharmprojects\callcenter-backend\venv\lib\site-packages\mysql\connector\connection_cext.py", line 523, in cmd_query
    self._cmysql.query(query,
_mysql_connector.MySQLInterfaceError: Unknown column 'position.position_id' in 'on clause'

During handling of the above exception, another exception occurred:

Traceback (most recent call last):
  File "c:\users\renow\pycharmprojects\callcenter-backend\venv\lib\site-packages\flask\app.py", line 2073, in wsgi_app
    response = self.full_dispatch_request()
  File "c:\users\renow\pycharmprojects\callcenter-backend\venv\lib\site-packages\flask\app.py", line 1518, in full_dispatch_request
    rv = self.handle_user_exception(e)
  File "c:\users\renow\pycharmprojects\callcenter-backend\venv\lib\site-packages\flask_cors\extension.py", line 165, in wrapped_function
    return cors_after_request(app.make_response(f(*args, **kwargs)))
  File "c:\users\renow\pycharmprojects\callcenter-backend\venv\lib\site-packages\flask\app.py", line 1516, in full_dispatch_request
    rv = self.dispatch_request()
  File "c:\users\renow\pycharmprojects\callcenter-backend\venv\lib\site-packages\flask\app.py", line 1502, in dispatch_request
    return self.ensure_sync(self.view_functions[rule.endpoint])(**req.view_args)
  File "C:\Users\renow\PycharmProjects\brimob-be\cc.py", line 35, in login_user
    res = authenticate_user(username, password)
  File "C:\Users\renow\PycharmProjects\brimob-be\cc.py", line 42, in authenticate_user
    cursor.execute(query, (username,))
  File "c:\users\renow\pycharmprojects\callcenter-backend\venv\lib\site-packages\mysql\connector\cursor_cext.py", line 269, in execute
    result = self._cnx.cmd_query(stmt, raw=self._raw,
  File "c:\users\renow\pycharmprojects\callcenter-backend\venv\lib\site-packages\mysql\connector\connection_cext.py", line 528, in cmd_query
    raise errors.get_mysql_exception(exc.errno, msg=exc.msg,
mysql.connector.errors.ProgrammingError: 1054 (42S22): Unknown column 'position.position_id' in 'on clause'
2022-03-23 00:40:20,299 INFO werkzeug Thread-2 : 127.0.0.1 - - [23/Mar/2022 00:40:20] "[35m[1mPOST /cc/login_user HTTP/1.1[0m" 500 -
2022-03-23 00:41:02,580 INFO werkzeug MainThread :  * Running on http://127.0.0.1:5000/ (Press CTRL+C to quit)
2022-03-23 00:41:04,705 ERROR main Thread-1 : Exception on /cc/login_user [POST]
Traceback (most recent call last):
  File "c:\users\renow\pycharmprojects\callcenter-backend\venv\lib\site-packages\mysql\connector\connection_cext.py", line 523, in cmd_query
    self._cmysql.query(query,
_mysql_connector.MySQLInterfaceError: Unknown column 'position.position_id' in 'on clause'

During handling of the above exception, another exception occurred:

Traceback (most recent call last):
  File "c:\users\renow\pycharmprojects\callcenter-backend\venv\lib\site-packages\flask\app.py", line 2073, in wsgi_app
    response = self.full_dispatch_request()
  File "c:\users\renow\pycharmprojects\callcenter-backend\venv\lib\site-packages\flask\app.py", line 1518, in full_dispatch_request
    rv = self.handle_user_exception(e)
  File "c:\users\renow\pycharmprojects\callcenter-backend\venv\lib\site-packages\flask_cors\extension.py", line 165, in wrapped_function
    return cors_after_request(app.make_response(f(*args, **kwargs)))
  File "c:\users\renow\pycharmprojects\callcenter-backend\venv\lib\site-packages\flask\app.py", line 1516, in full_dispatch_request
    rv = self.dispatch_request()
  File "c:\users\renow\pycharmprojects\callcenter-backend\venv\lib\site-packages\flask\app.py", line 1502, in dispatch_request
    return self.ensure_sync(self.view_functions[rule.endpoint])(**req.view_args)
  File "C:\Users\renow\PycharmProjects\brimob-be\cc.py", line 35, in login_user
    res = authenticate_user(username, password)
  File "C:\Users\renow\PycharmProjects\brimob-be\cc.py", line 42, in authenticate_user
    cursor.execute(query, (username,))
  File "c:\users\renow\pycharmprojects\callcenter-backend\venv\lib\site-packages\mysql\connector\cursor_cext.py", line 269, in execute
    result = self._cnx.cmd_query(stmt, raw=self._raw,
  File "c:\users\renow\pycharmprojects\callcenter-backend\venv\lib\site-packages\mysql\connector\connection_cext.py", line 528, in cmd_query
    raise errors.get_mysql_exception(exc.errno, msg=exc.msg,
mysql.connector.errors.ProgrammingError: 1054 (42S22): Unknown column 'position.position_id' in 'on clause'
2022-03-23 00:41:04,712 INFO werkzeug Thread-1 : 127.0.0.1 - - [23/Mar/2022 00:41:04] "[35m[1mPOST /cc/login_user HTTP/1.1[0m" 500 -
2022-03-23 00:41:06,111 ERROR main Thread-2 : Exception on /cc/login_user [POST]
Traceback (most recent call last):
  File "c:\users\renow\pycharmprojects\callcenter-backend\venv\lib\site-packages\mysql\connector\connection_cext.py", line 523, in cmd_query
    self._cmysql.query(query,
_mysql_connector.MySQLInterfaceError: Unknown column 'position.position_id' in 'on clause'

During handling of the above exception, another exception occurred:

Traceback (most recent call last):
  File "c:\users\renow\pycharmprojects\callcenter-backend\venv\lib\site-packages\flask\app.py", line 2073, in wsgi_app
    response = self.full_dispatch_request()
  File "c:\users\renow\pycharmprojects\callcenter-backend\venv\lib\site-packages\flask\app.py", line 1518, in full_dispatch_request
    rv = self.handle_user_exception(e)
  File "c:\users\renow\pycharmprojects\callcenter-backend\venv\lib\site-packages\flask_cors\extension.py", line 165, in wrapped_function
    return cors_after_request(app.make_response(f(*args, **kwargs)))
  File "c:\users\renow\pycharmprojects\callcenter-backend\venv\lib\site-packages\flask\app.py", line 1516, in full_dispatch_request
    rv = self.dispatch_request()
  File "c:\users\renow\pycharmprojects\callcenter-backend\venv\lib\site-packages\flask\app.py", line 1502, in dispatch_request
    return self.ensure_sync(self.view_functions[rule.endpoint])(**req.view_args)
  File "C:\Users\renow\PycharmProjects\brimob-be\cc.py", line 35, in login_user
    res = authenticate_user(username, password)
  File "C:\Users\renow\PycharmProjects\brimob-be\cc.py", line 42, in authenticate_user
    cursor.execute(query, (username,))
  File "c:\users\renow\pycharmprojects\callcenter-backend\venv\lib\site-packages\mysql\connector\cursor_cext.py", line 269, in execute
    result = self._cnx.cmd_query(stmt, raw=self._raw,
  File "c:\users\renow\pycharmprojects\callcenter-backend\venv\lib\site-packages\mysql\connector\connection_cext.py", line 528, in cmd_query
    raise errors.get_mysql_exception(exc.errno, msg=exc.msg,
mysql.connector.errors.ProgrammingError: 1054 (42S22): Unknown column 'position.position_id' in 'on clause'
2022-03-23 00:41:06,112 INFO werkzeug Thread-2 : 127.0.0.1 - - [23/Mar/2022 00:41:06] "[35m[1mPOST /cc/login_user HTTP/1.1[0m" 500 -
2022-03-23 00:41:56,274 INFO werkzeug MainThread :  * Running on http://127.0.0.1:5000/ (Press CTRL+C to quit)
2022-03-23 00:42:01,143 ERROR main Thread-1 : Exception on /cc/login_user [POST]
Traceback (most recent call last):
  File "c:\users\renow\pycharmprojects\callcenter-backend\venv\lib\site-packages\mysql\connector\connection_cext.py", line 523, in cmd_query
    self._cmysql.query(query,
_mysql_connector.MySQLInterfaceError: Unknown column 'position.position_id' in 'on clause'

During handling of the above exception, another exception occurred:

Traceback (most recent call last):
  File "c:\users\renow\pycharmprojects\callcenter-backend\venv\lib\site-packages\flask\app.py", line 2073, in wsgi_app
    response = self.full_dispatch_request()
  File "c:\users\renow\pycharmprojects\callcenter-backend\venv\lib\site-packages\flask\app.py", line 1518, in full_dispatch_request
    rv = self.handle_user_exception(e)
  File "c:\users\renow\pycharmprojects\callcenter-backend\venv\lib\site-packages\flask_cors\extension.py", line 165, in wrapped_function
    return cors_after_request(app.make_response(f(*args, **kwargs)))
  File "c:\users\renow\pycharmprojects\callcenter-backend\venv\lib\site-packages\flask\app.py", line 1516, in full_dispatch_request
    rv = self.dispatch_request()
  File "c:\users\renow\pycharmprojects\callcenter-backend\venv\lib\site-packages\flask\app.py", line 1502, in dispatch_request
    return self.ensure_sync(self.view_functions[rule.endpoint])(**req.view_args)
  File "C:\Users\renow\PycharmProjects\brimob-be\cc.py", line 35, in login_user
    res = authenticate_user(username, password)
  File "C:\Users\renow\PycharmProjects\brimob-be\cc.py", line 42, in authenticate_user
    cursor.execute(query, (username,))
  File "c:\users\renow\pycharmprojects\callcenter-backend\venv\lib\site-packages\mysql\connector\cursor_cext.py", line 269, in execute
    result = self._cnx.cmd_query(stmt, raw=self._raw,
  File "c:\users\renow\pycharmprojects\callcenter-backend\venv\lib\site-packages\mysql\connector\connection_cext.py", line 528, in cmd_query
    raise errors.get_mysql_exception(exc.errno, msg=exc.msg,
mysql.connector.errors.ProgrammingError: 1054 (42S22): Unknown column 'position.position_id' in 'on clause'
2022-03-23 00:42:01,149 INFO werkzeug Thread-1 : 127.0.0.1 - - [23/Mar/2022 00:42:01] "[35m[1mPOST /cc/login_user HTTP/1.1[0m" 500 -
2022-03-23 00:42:02,539 ERROR main Thread-2 : Exception on /cc/login_user [POST]
Traceback (most recent call last):
  File "c:\users\renow\pycharmprojects\callcenter-backend\venv\lib\site-packages\mysql\connector\connection_cext.py", line 523, in cmd_query
    self._cmysql.query(query,
_mysql_connector.MySQLInterfaceError: Unknown column 'position.position_id' in 'on clause'

During handling of the above exception, another exception occurred:

Traceback (most recent call last):
  File "c:\users\renow\pycharmprojects\callcenter-backend\venv\lib\site-packages\flask\app.py", line 2073, in wsgi_app
    response = self.full_dispatch_request()
  File "c:\users\renow\pycharmprojects\callcenter-backend\venv\lib\site-packages\flask\app.py", line 1518, in full_dispatch_request
    rv = self.handle_user_exception(e)
  File "c:\users\renow\pycharmprojects\callcenter-backend\venv\lib\site-packages\flask_cors\extension.py", line 165, in wrapped_function
    return cors_after_request(app.make_response(f(*args, **kwargs)))
  File "c:\users\renow\pycharmprojects\callcenter-backend\venv\lib\site-packages\flask\app.py", line 1516, in full_dispatch_request
    rv = self.dispatch_request()
  File "c:\users\renow\pycharmprojects\callcenter-backend\venv\lib\site-packages\flask\app.py", line 1502, in dispatch_request
    return self.ensure_sync(self.view_functions[rule.endpoint])(**req.view_args)
  File "C:\Users\renow\PycharmProjects\brimob-be\cc.py", line 35, in login_user
    res = authenticate_user(username, password)
  File "C:\Users\renow\PycharmProjects\brimob-be\cc.py", line 42, in authenticate_user
    cursor.execute(query, (username,))
  File "c:\users\renow\pycharmprojects\callcenter-backend\venv\lib\site-packages\mysql\connector\cursor_cext.py", line 269, in execute
    result = self._cnx.cmd_query(stmt, raw=self._raw,
  File "c:\users\renow\pycharmprojects\callcenter-backend\venv\lib\site-packages\mysql\connector\connection_cext.py", line 528, in cmd_query
    raise errors.get_mysql_exception(exc.errno, msg=exc.msg,
mysql.connector.errors.ProgrammingError: 1054 (42S22): Unknown column 'position.position_id' in 'on clause'
2022-03-23 00:42:02,543 INFO werkzeug Thread-2 : 127.0.0.1 - - [23/Mar/2022 00:42:02] "[35m[1mPOST /cc/login_user HTTP/1.1[0m" 500 -
2022-03-23 00:42:04,116 ERROR main Thread-3 : Exception on /cc/login_user [POST]
Traceback (most recent call last):
  File "c:\users\renow\pycharmprojects\callcenter-backend\venv\lib\site-packages\mysql\connector\connection_cext.py", line 523, in cmd_query
    self._cmysql.query(query,
_mysql_connector.MySQLInterfaceError: Unknown column 'position.position_id' in 'on clause'

During handling of the above exception, another exception occurred:

Traceback (most recent call last):
  File "c:\users\renow\pycharmprojects\callcenter-backend\venv\lib\site-packages\flask\app.py", line 2073, in wsgi_app
    response = self.full_dispatch_request()
  File "c:\users\renow\pycharmprojects\callcenter-backend\venv\lib\site-packages\flask\app.py", line 1518, in full_dispatch_request
    rv = self.handle_user_exception(e)
  File "c:\users\renow\pycharmprojects\callcenter-backend\venv\lib\site-packages\flask_cors\extension.py", line 165, in wrapped_function
    return cors_after_request(app.make_response(f(*args, **kwargs)))
  File "c:\users\renow\pycharmprojects\callcenter-backend\venv\lib\site-packages\flask\app.py", line 1516, in full_dispatch_request
    rv = self.dispatch_request()
  File "c:\users\renow\pycharmprojects\callcenter-backend\venv\lib\site-packages\flask\app.py", line 1502, in dispatch_request
    return self.ensure_sync(self.view_functions[rule.endpoint])(**req.view_args)
  File "C:\Users\renow\PycharmProjects\brimob-be\cc.py", line 35, in login_user
    res = authenticate_user(username, password)
  File "C:\Users\renow\PycharmProjects\brimob-be\cc.py", line 42, in authenticate_user
    cursor.execute(query, (username,))
  File "c:\users\renow\pycharmprojects\callcenter-backend\venv\lib\site-packages\mysql\connector\cursor_cext.py", line 269, in execute
    result = self._cnx.cmd_query(stmt, raw=self._raw,
  File "c:\users\renow\pycharmprojects\callcenter-backend\venv\lib\site-packages\mysql\connector\connection_cext.py", line 528, in cmd_query
    raise errors.get_mysql_exception(exc.errno, msg=exc.msg,
mysql.connector.errors.ProgrammingError: 1054 (42S22): Unknown column 'position.position_id' in 'on clause'
2022-03-23 00:42:04,117 INFO werkzeug Thread-3 : 127.0.0.1 - - [23/Mar/2022 00:42:04] "[35m[1mPOST /cc/login_user HTTP/1.1[0m" 500 -
2022-03-23 00:42:20,788 INFO werkzeug MainThread :  * Running on http://127.0.0.1:5000/ (Press CTRL+C to quit)
2022-03-23 00:42:26,794 INFO werkzeug Thread-1 : 127.0.0.1 - - [23/Mar/2022 00:42:26] "POST /cc/login_user HTTP/1.1" 200 -
2022-03-23 00:42:51,883 INFO werkzeug MainThread :  * Running on http://127.0.0.1:5000/ (Press CTRL+C to quit)
2022-03-23 00:42:53,656 INFO werkzeug Thread-1 : 127.0.0.1 - - [23/Mar/2022 00:42:53] "POST /cc/login_user HTTP/1.1" 200 -
2022-03-23 00:43:16,670 INFO werkzeug MainThread :  * Running on http://127.0.0.1:5000/ (Press CTRL+C to quit)
2022-03-23 00:43:20,188 ERROR main Thread-1 : Exception on /cc/login_user [POST]
Traceback (most recent call last):
  File "c:\users\renow\pycharmprojects\callcenter-backend\venv\lib\site-packages\mysql\connector\connection_cext.py", line 523, in cmd_query
    self._cmysql.query(query,
_mysql_connector.MySQLInterfaceError: Unknown column 'position.position_id' in 'on clause'

During handling of the above exception, another exception occurred:

Traceback (most recent call last):
  File "c:\users\renow\pycharmprojects\callcenter-backend\venv\lib\site-packages\flask\app.py", line 2073, in wsgi_app
    response = self.full_dispatch_request()
  File "c:\users\renow\pycharmprojects\callcenter-backend\venv\lib\site-packages\flask\app.py", line 1518, in full_dispatch_request
    rv = self.handle_user_exception(e)
  File "c:\users\renow\pycharmprojects\callcenter-backend\venv\lib\site-packages\flask_cors\extension.py", line 165, in wrapped_function
    return cors_after_request(app.make_response(f(*args, **kwargs)))
  File "c:\users\renow\pycharmprojects\callcenter-backend\venv\lib\site-packages\flask\app.py", line 1516, in full_dispatch_request
    rv = self.dispatch_request()
  File "c:\users\renow\pycharmprojects\callcenter-backend\venv\lib\site-packages\flask\app.py", line 1502, in dispatch_request
    return self.ensure_sync(self.view_functions[rule.endpoint])(**req.view_args)
  File "C:\Users\renow\PycharmProjects\brimob-be\cc.py", line 35, in login_user
    res = authenticate_user(username, password)
  File "C:\Users\renow\PycharmProjects\brimob-be\cc.py", line 42, in authenticate_user
    cursor.execute(query, (username,))
  File "c:\users\renow\pycharmprojects\callcenter-backend\venv\lib\site-packages\mysql\connector\cursor_cext.py", line 269, in execute
    result = self._cnx.cmd_query(stmt, raw=self._raw,
  File "c:\users\renow\pycharmprojects\callcenter-backend\venv\lib\site-packages\mysql\connector\connection_cext.py", line 528, in cmd_query
    raise errors.get_mysql_exception(exc.errno, msg=exc.msg,
mysql.connector.errors.ProgrammingError: 1054 (42S22): Unknown column 'position.position_id' in 'on clause'
2022-03-23 00:43:20,196 INFO werkzeug Thread-1 : 127.0.0.1 - - [23/Mar/2022 00:43:20] "[35m[1mPOST /cc/login_user HTTP/1.1[0m" 500 -
2022-03-23 00:45:17,715 INFO werkzeug MainThread :  * Running on http://127.0.0.1:5000/ (Press CTRL+C to quit)
2022-03-23 00:45:19,560 ERROR main Thread-1 : Exception on /cc/login_user [POST]
Traceback (most recent call last):
  File "c:\users\renow\pycharmprojects\callcenter-backend\venv\lib\site-packages\mysql\connector\connection_cext.py", line 523, in cmd_query
    self._cmysql.query(query,
_mysql_connector.MySQLInterfaceError: Unknown column 'work_order.position_id' in 'on clause'

During handling of the above exception, another exception occurred:

Traceback (most recent call last):
  File "c:\users\renow\pycharmprojects\callcenter-backend\venv\lib\site-packages\flask\app.py", line 2073, in wsgi_app
    response = self.full_dispatch_request()
  File "c:\users\renow\pycharmprojects\callcenter-backend\venv\lib\site-packages\flask\app.py", line 1518, in full_dispatch_request
    rv = self.handle_user_exception(e)
  File "c:\users\renow\pycharmprojects\callcenter-backend\venv\lib\site-packages\flask_cors\extension.py", line 165, in wrapped_function
    return cors_after_request(app.make_response(f(*args, **kwargs)))
  File "c:\users\renow\pycharmprojects\callcenter-backend\venv\lib\site-packages\flask\app.py", line 1516, in full_dispatch_request
    rv = self.dispatch_request()
  File "c:\users\renow\pycharmprojects\callcenter-backend\venv\lib\site-packages\flask\app.py", line 1502, in dispatch_request
    return self.ensure_sync(self.view_functions[rule.endpoint])(**req.view_args)
  File "C:\Users\renow\PycharmProjects\brimob-be\cc.py", line 35, in login_user
    res = authenticate_user(username, password)
  File "C:\Users\renow\PycharmProjects\brimob-be\cc.py", line 42, in authenticate_user
    cursor.execute(query, (username,))
  File "c:\users\renow\pycharmprojects\callcenter-backend\venv\lib\site-packages\mysql\connector\cursor_cext.py", line 269, in execute
    result = self._cnx.cmd_query(stmt, raw=self._raw,
  File "c:\users\renow\pycharmprojects\callcenter-backend\venv\lib\site-packages\mysql\connector\connection_cext.py", line 528, in cmd_query
    raise errors.get_mysql_exception(exc.errno, msg=exc.msg,
mysql.connector.errors.ProgrammingError: 1054 (42S22): Unknown column 'work_order.position_id' in 'on clause'
2022-03-23 00:45:19,566 INFO werkzeug Thread-1 : 127.0.0.1 - - [23/Mar/2022 00:45:19] "[35m[1mPOST /cc/login_user HTTP/1.1[0m" 500 -
2022-03-23 00:45:21,274 ERROR main Thread-2 : Exception on /cc/login_user [POST]
Traceback (most recent call last):
  File "c:\users\renow\pycharmprojects\callcenter-backend\venv\lib\site-packages\mysql\connector\connection_cext.py", line 523, in cmd_query
    self._cmysql.query(query,
_mysql_connector.MySQLInterfaceError: Unknown column 'work_order.position_id' in 'on clause'

During handling of the above exception, another exception occurred:

Traceback (most recent call last):
  File "c:\users\renow\pycharmprojects\callcenter-backend\venv\lib\site-packages\flask\app.py", line 2073, in wsgi_app
    response = self.full_dispatch_request()
  File "c:\users\renow\pycharmprojects\callcenter-backend\venv\lib\site-packages\flask\app.py", line 1518, in full_dispatch_request
    rv = self.handle_user_exception(e)
  File "c:\users\renow\pycharmprojects\callcenter-backend\venv\lib\site-packages\flask_cors\extension.py", line 165, in wrapped_function
    return cors_after_request(app.make_response(f(*args, **kwargs)))
  File "c:\users\renow\pycharmprojects\callcenter-backend\venv\lib\site-packages\flask\app.py", line 1516, in full_dispatch_request
    rv = self.dispatch_request()
  File "c:\users\renow\pycharmprojects\callcenter-backend\venv\lib\site-packages\flask\app.py", line 1502, in dispatch_request
    return self.ensure_sync(self.view_functions[rule.endpoint])(**req.view_args)
  File "C:\Users\renow\PycharmProjects\brimob-be\cc.py", line 35, in login_user
    res = authenticate_user(username, password)
  File "C:\Users\renow\PycharmProjects\brimob-be\cc.py", line 42, in authenticate_user
    cursor.execute(query, (username,))
  File "c:\users\renow\pycharmprojects\callcenter-backend\venv\lib\site-packages\mysql\connector\cursor_cext.py", line 269, in execute
    result = self._cnx.cmd_query(stmt, raw=self._raw,
  File "c:\users\renow\pycharmprojects\callcenter-backend\venv\lib\site-packages\mysql\connector\connection_cext.py", line 528, in cmd_query
    raise errors.get_mysql_exception(exc.errno, msg=exc.msg,
mysql.connector.errors.ProgrammingError: 1054 (42S22): Unknown column 'work_order.position_id' in 'on clause'
2022-03-23 00:45:21,275 INFO werkzeug Thread-2 : 127.0.0.1 - - [23/Mar/2022 00:45:21] "[35m[1mPOST /cc/login_user HTTP/1.1[0m" 500 -
2022-03-23 00:45:41,183 INFO werkzeug MainThread :  * Running on http://127.0.0.1:5000/ (Press CTRL+C to quit)
2022-03-23 00:45:41,485 INFO werkzeug Thread-1 : 127.0.0.1 - - [23/Mar/2022 00:45:41] "POST /cc/login_user HTTP/1.1" 200 -
2022-03-23 01:18:59,891 INFO werkzeug MainThread :  * Running on http://127.0.0.1:5000/ (Press CTRL+C to quit)
2022-03-23 01:19:03,596 INFO werkzeug Thread-1 : 127.0.0.1 - - [23/Mar/2022 01:19:03] "POST /cc/login_user HTTP/1.1" 200 -
2022-03-23 01:19:25,601 INFO werkzeug MainThread :  * Running on http://127.0.0.1:5000/ (Press CTRL+C to quit)
2022-03-23 01:19:30,661 INFO werkzeug Thread-1 : 127.0.0.1 - - [23/Mar/2022 01:19:30] "POST /cc/login_user HTTP/1.1" 200 -
2022-03-23 21:19:21,867 INFO werkzeug MainThread :  * Running on http://127.0.0.1:5000/ (Press CTRL+C to quit)
2022-03-23 21:19:29,652 INFO werkzeug Thread-1 : 127.0.0.1 - - [23/Mar/2022 21:19:29] "POST /cc/login_user HTTP/1.1" 200 -
2022-03-23 21:22:05,703 INFO werkzeug Thread-2 : 127.0.0.1 - - [23/Mar/2022 21:22:05] "POST /cc/login_user HTTP/1.1" 200 -
2022-03-23 21:51:26,916 INFO werkzeug MainThread :  * Running on http://127.0.0.1:5000/ (Press CTRL+C to quit)
2022-03-23 21:51:28,032 INFO werkzeug Thread-1 : 127.0.0.1 - - [23/Mar/2022 21:51:28] "POST /cc/login_user HTTP/1.1" 200 -
2022-03-23 21:54:41,991 INFO werkzeug MainThread :  * Running on http://127.0.0.1:5000/ (Press CTRL+C to quit)
2022-03-23 21:58:50,504 INFO werkzeug Thread-1 : 127.0.0.1 - - [23/Mar/2022 21:58:50] "POST /cc/login_user HTTP/1.1" 200 -
2022-03-23 22:01:23,525 INFO werkzeug MainThread :  * Running on http://127.0.0.1:5000/ (Press CTRL+C to quit)
2022-03-23 22:01:24,715 INFO werkzeug Thread-1 : 127.0.0.1 - - [23/Mar/2022 22:01:24] "POST /cc/login_user HTTP/1.1" 200 -
2022-03-23 22:01:26,833 INFO werkzeug Thread-2 : 127.0.0.1 - - [23/Mar/2022 22:01:26] "POST /cc/login_user HTTP/1.1" 200 -
2022-03-23 22:01:49,039 INFO werkzeug MainThread :  * Running on http://127.0.0.1:5000/ (Press CTRL+C to quit)
2022-03-23 22:01:50,572 INFO werkzeug Thread-1 : 127.0.0.1 - - [23/Mar/2022 22:01:50] "POST /cc/login_user HTTP/1.1" 200 -
2022-03-23 22:02:48,567 INFO werkzeug MainThread :  * Running on http://127.0.0.1:5000/ (Press CTRL+C to quit)
2022-03-23 22:03:05,258 INFO werkzeug Thread-1 : 127.0.0.1 - - [23/Mar/2022 22:03:05] "POST /cc/login_user HTTP/1.1" 200 -
2022-03-23 22:05:10,357 INFO werkzeug MainThread :  * Running on http://127.0.0.1:5000/ (Press CTRL+C to quit)
2022-03-23 22:05:13,113 ERROR main Thread-1 : Exception on /cc/login_user [POST]
Traceback (most recent call last):
  File "c:\users\renow\pycharmprojects\callcenter-backend\venv\lib\site-packages\mysql\connector\connection_cext.py", line 523, in cmd_query
    self._cmysql.query(query,
_mysql_connector.MySQLInterfaceError: You have an error in your SQL syntax; check the manual that corresponds to your MySQL server version for the right syntax to use near 'id, region.id as region id FROM user LEFT JOIN position ON position.id = user.po' at line 1

During handling of the above exception, another exception occurred:

Traceback (most recent call last):
  File "c:\users\renow\pycharmprojects\callcenter-backend\venv\lib\site-packages\flask\app.py", line 2073, in wsgi_app
    response = self.full_dispatch_request()
  File "c:\users\renow\pycharmprojects\callcenter-backend\venv\lib\site-packages\flask\app.py", line 1518, in full_dispatch_request
    rv = self.handle_user_exception(e)
  File "c:\users\renow\pycharmprojects\callcenter-backend\venv\lib\site-packages\flask_cors\extension.py", line 165, in wrapped_function
    return cors_after_request(app.make_response(f(*args, **kwargs)))
  File "c:\users\renow\pycharmprojects\callcenter-backend\venv\lib\site-packages\flask\app.py", line 1516, in full_dispatch_request
    rv = self.dispatch_request()
  File "c:\users\renow\pycharmprojects\callcenter-backend\venv\lib\site-packages\flask\app.py", line 1502, in dispatch_request
    return self.ensure_sync(self.view_functions[rule.endpoint])(**req.view_args)
  File "C:\Users\renow\PycharmProjects\brimob-be\cc.py", line 35, in login_user
    res = authenticate_user(username, password)
  File "C:\Users\renow\PycharmProjects\brimob-be\cc.py", line 45, in authenticate_user
    cursor.execute(query, (username,))
  File "c:\users\renow\pycharmprojects\callcenter-backend\venv\lib\site-packages\mysql\connector\cursor_cext.py", line 269, in execute
    result = self._cnx.cmd_query(stmt, raw=self._raw,
  File "c:\users\renow\pycharmprojects\callcenter-backend\venv\lib\site-packages\mysql\connector\connection_cext.py", line 528, in cmd_query
    raise errors.get_mysql_exception(exc.errno, msg=exc.msg,
mysql.connector.errors.ProgrammingError: 1064 (42000): You have an error in your SQL syntax; check the manual that corresponds to your MySQL server version for the right syntax to use near 'id, region.id as region id FROM user LEFT JOIN position ON position.id = user.po' at line 1
2022-03-23 22:05:13,185 INFO werkzeug Thread-1 : 127.0.0.1 - - [23/Mar/2022 22:05:13] "[35m[1mPOST /cc/login_user HTTP/1.1[0m" 500 -
2022-03-23 22:05:58,831 INFO werkzeug MainThread :  * Running on http://127.0.0.1:5000/ (Press CTRL+C to quit)
2022-03-23 22:06:17,959 INFO werkzeug Thread-1 : 127.0.0.1 - - [23/Mar/2022 22:06:17] "POST /cc/login_user HTTP/1.1" 200 -
2022-03-24 10:14:23,854 INFO werkzeug MainThread :  * Running on http://127.0.0.1:5000/ (Press CTRL+C to quit)
2022-03-24 10:14:25,817 INFO werkzeug Thread-1 : 127.0.0.1 - - [24/Mar/2022 10:14:25] "POST /cc/login_user HTTP/1.1" 200 -
2022-03-24 10:15:38,069 INFO werkzeug MainThread :  * Running on http://127.0.0.1:5000/ (Press CTRL+C to quit)
2022-03-24 10:15:41,590 INFO werkzeug Thread-1 : 127.0.0.1 - - [24/Mar/2022 10:15:41] "POST /cc/login_user HTTP/1.1" 200 -
2022-03-24 10:20:11,869 INFO werkzeug MainThread :  * Running on http://127.0.0.1:5000/ (Press CTRL+C to quit)
2022-03-24 10:20:12,783 INFO werkzeug Thread-1 : 127.0.0.1 - - [24/Mar/2022 10:20:12] "POST /cc/login_user HTTP/1.1" 200 -
2022-03-24 10:26:05,354 INFO werkzeug MainThread :  * Running on http://127.0.0.1:5000/ (Press CTRL+C to quit)
2022-03-24 10:26:49,480 ERROR main Thread-1 : Exception on /cc/login_user [POST]
Traceback (most recent call last):
  File "c:\users\renow\pycharmprojects\callcenter-backend\venv\lib\site-packages\flask\app.py", line 2073, in wsgi_app
    response = self.full_dispatch_request()
  File "c:\users\renow\pycharmprojects\callcenter-backend\venv\lib\site-packages\flask\app.py", line 1518, in full_dispatch_request
    rv = self.handle_user_exception(e)
  File "c:\users\renow\pycharmprojects\callcenter-backend\venv\lib\site-packages\flask_cors\extension.py", line 165, in wrapped_function
    return cors_after_request(app.make_response(f(*args, **kwargs)))
  File "c:\users\renow\pycharmprojects\callcenter-backend\venv\lib\site-packages\flask\app.py", line 1516, in full_dispatch_request
    rv = self.dispatch_request()
  File "c:\users\renow\pycharmprojects\callcenter-backend\venv\lib\site-packages\flask\app.py", line 1502, in dispatch_request
    return self.ensure_sync(self.view_functions[rule.endpoint])(**req.view_args)
  File "C:\Users\renow\PycharmProjects\brimob-be\cc.py", line 35, in login_user
    res = authenticate_user(username, password)
NameError: name 'authenticate_user' is not defined
2022-03-24 10:26:49,516 INFO werkzeug Thread-1 : 127.0.0.1 - - [24/Mar/2022 10:26:49] "[35m[1mPOST /cc/login_user HTTP/1.1[0m" 500 -
2022-03-24 10:27:07,672 INFO werkzeug MainThread :  * Running on http://127.0.0.1:5000/ (Press CTRL+C to quit)
2022-03-24 10:27:11,411 INFO werkzeug Thread-1 : 127.0.0.1 - - [24/Mar/2022 10:27:11] "POST /cc/login_user HTTP/1.1" 200 -
2022-03-24 10:27:51,850 INFO werkzeug MainThread :  * Running on http://127.0.0.1:5000/ (Press CTRL+C to quit)
2022-03-24 10:27:56,772 INFO werkzeug Thread-1 : 127.0.0.1 - - [24/Mar/2022 10:27:56] "POST /cc/login_user HTTP/1.1" 200 -
2022-03-24 10:28:38,446 INFO werkzeug MainThread :  * Running on http://127.0.0.1:5000/ (Press CTRL+C to quit)
2022-03-24 10:34:41,483 INFO werkzeug MainThread :  * Running on http://127.0.0.1:5000/ (Press CTRL+C to quit)
2022-03-24 10:34:45,892 INFO werkzeug Thread-1 : 127.0.0.1 - - [24/Mar/2022 10:34:45] "POST /cc/login_user HTTP/1.1" 200 -
2022-03-24 10:43:43,823 INFO werkzeug MainThread :  * Running on http://127.0.0.1:5000/ (Press CTRL+C to quit)
2022-03-24 19:50:56,396 INFO werkzeug MainThread :  * Running on http://127.0.0.1:5000/ (Press CTRL+C to quit)
2022-03-24 19:51:38,831 INFO werkzeug Thread-1 (process_request_thread) : 127.0.0.1 - - [24/Mar/2022 19:51:38] "POST /cc/login_user HTTP/1.1" 200 -
2022-03-24 19:55:48,259 ERROR main Thread-2 (process_request_thread) : Exception on /cc/login_user [POST]
Traceback (most recent call last):
  File "c:\users\renow\pycharmprojects\brimob-be\venv\lib\site-packages\flask\app.py", line 2073, in wsgi_app
    response = self.full_dispatch_request()
  File "c:\users\renow\pycharmprojects\brimob-be\venv\lib\site-packages\flask\app.py", line 1518, in full_dispatch_request
    rv = self.handle_user_exception(e)
  File "c:\users\renow\pycharmprojects\brimob-be\venv\lib\site-packages\flask_cors\extension.py", line 165, in wrapped_function
    return cors_after_request(app.make_response(f(*args, **kwargs)))
  File "c:\users\renow\pycharmprojects\brimob-be\venv\lib\site-packages\flask\app.py", line 1516, in full_dispatch_request
    rv = self.dispatch_request()
  File "c:\users\renow\pycharmprojects\brimob-be\venv\lib\site-packages\flask\app.py", line 1502, in dispatch_request
    return self.ensure_sync(self.view_functions[rule.endpoint])(**req.view_args)
  File "C:\Users\renow\PycharmProjects\brimob-be\cc.py", line 35, in login_user
    res = authenticate_user(username, password)
  File "C:\Users\renow\PycharmProjects\brimob-be\cc.py", line 88, in authenticate_user
    res['position_id'] = position_id
UnboundLocalError: local variable 'position_id' referenced before assignment
2022-03-24 19:55:48,268 INFO werkzeug Thread-2 (process_request_thread) : 127.0.0.1 - - [24/Mar/2022 19:55:48] "[35m[1mPOST /cc/login_user HTTP/1.1[0m" 500 -
2022-03-24 19:57:00,612 INFO werkzeug MainThread :  * Running on http://127.0.0.1:5000/ (Press CTRL+C to quit)
2022-03-24 19:57:03,133 INFO werkzeug Thread-1 (process_request_thread) : 127.0.0.1 - - [24/Mar/2022 19:57:03] "POST /cc/login_user HTTP/1.1" 200 -
2022-03-24 19:57:07,850 INFO werkzeug Thread-2 (process_request_thread) : 127.0.0.1 - - [24/Mar/2022 19:57:07] "POST /cc/login_user HTTP/1.1" 200 -
2022-03-24 20:00:06,607 INFO werkzeug MainThread :  * Running on http://127.0.0.1:5000/ (Press CTRL+C to quit)
2022-03-24 20:01:06,788 INFO werkzeug MainThread :  * Running on http://127.0.0.1:5000/ (Press CTRL+C to quit)
2022-03-24 20:01:45,407 ERROR main Thread-1 (process_request_thread) : Exception on /cc/simpan_user [POST]
Traceback (most recent call last):
  File "c:\users\renow\pycharmprojects\brimob-be\venv\lib\site-packages\mysql\connector\cursor_cext.py", line 66, in __call__
    return self.params[index]
IndexError: tuple index out of range

During handling of the above exception, another exception occurred:

Traceback (most recent call last):
  File "c:\users\renow\pycharmprojects\brimob-be\venv\lib\site-packages\flask\app.py", line 2073, in wsgi_app
    response = self.full_dispatch_request()
  File "c:\users\renow\pycharmprojects\brimob-be\venv\lib\site-packages\flask\app.py", line 1518, in full_dispatch_request
    rv = self.handle_user_exception(e)
  File "c:\users\renow\pycharmprojects\brimob-be\venv\lib\site-packages\flask_cors\extension.py", line 165, in wrapped_function
    return cors_after_request(app.make_response(f(*args, **kwargs)))
  File "c:\users\renow\pycharmprojects\brimob-be\venv\lib\site-packages\flask\app.py", line 1516, in full_dispatch_request
    rv = self.dispatch_request()
  File "c:\users\renow\pycharmprojects\brimob-be\venv\lib\site-packages\flask\app.py", line 1502, in dispatch_request
    return self.ensure_sync(self.view_functions[rule.endpoint])(**req.view_args)
  File "C:\Users\renow\PycharmProjects\brimob-be\cc.py", line 123, in simpan_user
    cursor.execute(query, (username, hashed,level_user,position_id,))
  File "c:\users\renow\pycharmprojects\brimob-be\venv\lib\site-packages\mysql\connector\cursor_cext.py", line 263, in execute
    stmt = RE_PY_PARAM.sub(psub, stmt)
  File "c:\users\renow\pycharmprojects\brimob-be\venv\lib\site-packages\mysql\connector\cursor_cext.py", line 68, in __call__
    raise errors.ProgrammingError(
mysql.connector.errors.ProgrammingError: Not enough parameters for the SQL statement
2022-03-24 20:01:45,410 INFO werkzeug Thread-1 (process_request_thread) : 127.0.0.1 - - [24/Mar/2022 20:01:45] "[35m[1mPOST /cc/simpan_user HTTP/1.1[0m" 500 -
2022-03-24 20:02:01,738 INFO werkzeug Thread-2 (process_request_thread) : 127.0.0.1 - - [24/Mar/2022 20:02:01] "POST /cc/simpan_user HTTP/1.1" 200 -
2022-03-24 20:02:14,284 ERROR main Thread-3 (process_request_thread) : Exception on /cc/simpan_user [POST]
Traceback (most recent call last):
  File "c:\users\renow\pycharmprojects\brimob-be\venv\lib\site-packages\mysql\connector\cursor_cext.py", line 66, in __call__
    return self.params[index]
IndexError: tuple index out of range

During handling of the above exception, another exception occurred:

Traceback (most recent call last):
  File "c:\users\renow\pycharmprojects\brimob-be\venv\lib\site-packages\flask\app.py", line 2073, in wsgi_app
    response = self.full_dispatch_request()
  File "c:\users\renow\pycharmprojects\brimob-be\venv\lib\site-packages\flask\app.py", line 1518, in full_dispatch_request
    rv = self.handle_user_exception(e)
  File "c:\users\renow\pycharmprojects\brimob-be\venv\lib\site-packages\flask_cors\extension.py", line 165, in wrapped_function
    return cors_after_request(app.make_response(f(*args, **kwargs)))
  File "c:\users\renow\pycharmprojects\brimob-be\venv\lib\site-packages\flask\app.py", line 1516, in full_dispatch_request
    rv = self.dispatch_request()
  File "c:\users\renow\pycharmprojects\brimob-be\venv\lib\site-packages\flask\app.py", line 1502, in dispatch_request
    return self.ensure_sync(self.view_functions[rule.endpoint])(**req.view_args)
  File "C:\Users\renow\PycharmProjects\brimob-be\cc.py", line 123, in simpan_user
    cursor.execute(query, (username, hashed,level_user,position_id,))
  File "c:\users\renow\pycharmprojects\brimob-be\venv\lib\site-packages\mysql\connector\cursor_cext.py", line 263, in execute
    stmt = RE_PY_PARAM.sub(psub, stmt)
  File "c:\users\renow\pycharmprojects\brimob-be\venv\lib\site-packages\mysql\connector\cursor_cext.py", line 68, in __call__
    raise errors.ProgrammingError(
mysql.connector.errors.ProgrammingError: Not enough parameters for the SQL statement
2022-03-24 20:02:14,286 INFO werkzeug Thread-3 (process_request_thread) : 127.0.0.1 - - [24/Mar/2022 20:02:14] "[35m[1mPOST /cc/simpan_user HTTP/1.1[0m" 500 -
2022-03-24 20:03:10,249 INFO werkzeug MainThread :  * Running on http://127.0.0.1:5000/ (Press CTRL+C to quit)
2022-03-24 20:03:11,497 INFO werkzeug Thread-1 (process_request_thread) : 127.0.0.1 - - [24/Mar/2022 20:03:11] "POST /cc/simpan_user HTTP/1.1" 200 -
